Workbook
Name CreditList: 'Payment Method'!$A$2:$A$4
Name PaymentList: 'Payment Method'!$A$2:$A$15
Name CategoryList: LongFormat!$A$2:$A$962
Name SubCategoryList: LongFormat!$B$2:$B$962
Name ShopList: 'Categories Wide'!$O$2:$O$50

Sheet Transaction
A1: Date | B1: Category | C1: Sub-Category | D1: Amount | E1: Pay Medthod | F1: Status | G1: Shop | H1: Note | I1: Year | J1: Month
A2: 45678 | B2: Investment | C2: US Stock | D2: 4732.46 | E2: Mobile Banking | I2: =IF(A2<>"", "_"&YEAR(A2)&"_", "") -> _2025_ | J2: =IF(A2<>"", "_"&MONTH(A2)&"_", "") -> _1_
A3: 45681 | B3: Investment | C3: US Stock | D3: 4344.1 | E3: Mobile Banking | I3: =IF(A3<>"", "_"&YEAR(A3)&"_", "") -> _2025_ | J3: =IF(A3<>"", "_"&MONTH(A3)&"_", "") -> _1_
A4: 45697 | B4: Investment | C4: US Stock | D4: 10000 | E4: Mobile Banking | I4: =IF(A4<>"", "_"&YEAR(A4)&"_", "") -> _2025_ | J4: =IF(A4<>"", "_"&MONTH(A4)&"_", "") -> _2_
A5: 45702 | B5: Investment | C5: US Stock | D5: 2200 | E5: Mobile Banking | I5: =IF(A5<>"", "_"&YEAR(A5)&"_", "") -> _2025_ | J5: =IF(A5<>"", "_"&MONTH(A5)&"_", "") -> _2_
A6: 45713 | B6: Investment | C6: US Stock | D6: 4500 | E6: Mobile Banking | I6: =IF(A6<>"", "_"&YEAR(A6)&"_", "") -> _2025_ | J6: =IF(A6<>"", "_"&MONTH(A6)&"_", "") -> _2_
A7: 45734 | B7: Investment | C7: US Stock | D7: 3000 | E7: Mobile Banking | I7: =IF(A7<>"", "_"&YEAR(A7)&"_", "") -> _2025_ | J7: =IF(A7<>"", "_"&MONTH(A7)&"_", "") -> _3_
A8: 45734 | B8: Investment | C8: TH Fund | D8: 2000 | E8: Mobile Banking | H8: SCBS&P500E, SCBNSQ(E) | I8: =IF(A8<>"", "_"&YEAR(A8)&"_", "") -> _2025_ | J8: =IF(A8<>"", "_"&MONTH(A8)&"_", "") -> _3_
A9: 45738 | B9: Transportation | C9: Fuel | D9: 650 | E9: TTB So Smart | F9: Credit Payment | G9: Bangchak | I9: =IF(A9<>"", "_"&YEAR(A9)&"_", "") -> _2025_ | J9: =IF(A9<>"", "_"&MONTH(A9)&"_", "") -> _3_
A10: 45738 | B10: Food & Drink | C10: Others | D10: 89 | E10: TTB So Smart | F10: Credit Payment | H10: ข้าวยำ | I10: =IF(A10<>"", "_"&YEAR(A10)&"_", "") -> _2025_ | J10: =IF(A10<>"", "_"&MONTH(A10)&"_", "") -> _3_
A11: 45741 | B11: Monthly Pay | C11: Salary | D11: 41044.86 | E11: Mobile Banking | I11: =IF(A11<>"", "_"&YEAR(A11)&"_", "") -> _2025_ | J11: =IF(A11<>"", "_"&MONTH(A11)&"_", "") -> _3_
A12: 45741 | B12: Investment | C12: US Stock | D12: 500 | E12: Mobile Banking | I12: =IF(A12<>"", "_"&YEAR(A12)&"_", "") -> _2025_ | J12: =IF(A12<>"", "_"&MONTH(A12)&"_", "") -> _3_
A13: 45741 | B13: Investment | C13: US Stock | D13: 5500 | E13: Mobile Banking | I13: =IF(A13<>"", "_"&YEAR(A13)&"_", "") -> _2025_ | J13: =IF(A13<>"", "_"&MONTH(A13)&"_", "") -> _3_
A14: 45743 | B14: Food & Drink | C14: Main meals | D14: 200 | E14: TTB So Smart | F14: Credit Payment | G14: Mc Donald | I14: =IF(A14<>"", "_"&YEAR(A14)&"_", "") -> _2025_ | J14: =IF(A14<>"", "_"&MONTH(A14)&"_", "") -> _3_
A15: 45743 | B15: Items | C15: Household Items | D15: 146 | E15: TTB So Smart | F15: Credit Payment | H15: หลอดไฟ | I15: =IF(A15<>"", "_"&YEAR(A15)&"_", "") -> _2025_ | J15: =IF(A15<>"", "_"&MONTH(A15)&"_", "") -> _3_
A16: 45744 | B16: Food & Drink | C16: Main meals | D16: 159 | E16: TTB So Smart | F16: Credit Payment | G16: KFC | I16: =IF(A16<>"", "_"&YEAR(A16)&"_", "") -> _2025_ | J16: =IF(A16<>"", "_"&MONTH(A16)&"_", "") -> _3_
A17: 45745 | B17: Food & Drink | C17: Snacks | D17: 134 | E17: TTB So Smart | F17: Credit Payment | I17: =IF(A17<>"", "_"&YEAR(A17)&"_", "") -> _2025_ | J17: =IF(A17<>"", "_"&MONTH(A17)&"_", "") -> _3_
A18: 45746 | B18: Food & Drink | C18: Drinks | D18: 50 | E18: TTB So Smart | F18: Credit Payment | G18: Amazon | H18: ชาเขียว | I18: =IF(A18<>"", "_"&YEAR(A18)&"_", "") -> _2025_ | J18: =IF(A18<>"", "_"&MONTH(A18)&"_", "") -> _3_
A19: 45752 | B19: Food & Drink | C19: Groceries | D19: 153.25 | E19: TTB So Smart | F19: Credit Payment | G19: Lotus | H19: ผลไม้ ขนม | I19: =IF(A19<>"", "_"&YEAR(A19)&"_", "") -> _2025_ | J19: =IF(A19<>"", "_"&MONTH(A19)&"_", "") -> _4_
A20: 45753 | B20: Food & Drink | C20: Groceries | D20: 347.25 | E20: TTB So Smart | F20: Credit Payment | G20: Lotus | H20: เนื้อ ผัก | I20: =IF(A20<>"", "_"&YEAR(A20)&"_", "") -> _2025_ | J20: =IF(A20<>"", "_"&MONTH(A20)&"_", "") -> _4_
A21: 45753 | B21: Hobby | C21: Tree | D21: 150 | E21: Mobile Banking | H21: ต้นไม้หน้าคอม | I21: =IF(A21<>"", "_"&YEAR(A21)&"_", "") -> _2025_ | J21: =IF(A21<>"", "_"&MONTH(A21)&"_", "") -> _4_
A22: 45754 | B22: Service | C22: Subscription | D22: 19 | E22: Mobile Banking | H22: Subscribe K.Earthh Evans | I22: =IF(A22<>"", "_"&YEAR(A22)&"_", "") -> _2025_ | J22: =IF(A22<>"", "_"&MONTH(A22)&"_", "") -> _4_
A23: 45754 | B23: Food & Drink | C23: Groceries | D23: 110.75 | E23: TTB So Smart | F23: Credit Payment | G23: Lotus | H23: ผลไม้ | I23: =IF(A23<>"", "_"&YEAR(A23)&"_", "") -> _2025_ | J23: =IF(A23<>"", "_"&MONTH(A23)&"_", "") -> _4_
A24: 45755 | B24: Service | C24: Haircut | D24: 120 | E24: Mobile Banking | I24: =IF(A24<>"", "_"&YEAR(A24)&"_", "") -> _2025_ | J24: =IF(A24<>"", "_"&MONTH(A24)&"_", "") -> _4_
A25: 45755 | B25: Food & Drink | C25: Snacks | D25: 124.5 | E25: Mobile Banking | G25: 7-Eleven | H25: ขนม | I25: =IF(A25<>"", "_"&YEAR(A25)&"_", "") -> _2025_ | J25: =IF(A25<>"", "_"&MONTH(A25)&"_", "") -> _4_
A26: 45755 | B26: Food & Drink | C26: Snacks | D26: 40 | E26: Mobile Banking | H26: ลูกชิ้น | I26: =IF(A26<>"", "_"&YEAR(A26)&"_", "") -> _2025_ | J26: =IF(A26<>"", "_"&MONTH(A26)&"_", "") -> _4_
A27: 45757 | B27: Food & Drink | C27: Others | D27: 55 | E27: Mobile Banking | G27: 7-Eleven | I27: =IF(A27<>"", "_"&YEAR(A27)&"_", "") -> _2025_ | J27: =IF(A27<>"", "_"&MONTH(A27)&"_", "") -> _4_
A28: 45757 | B28: Food & Drink | C28: Others | D28: 127 | E28: Mobile Banking | G28: 7-Eleven | H28: ของกินกลางวัน | I28: =IF(A28<>"", "_"&YEAR(A28)&"_", "") -> _2025_ | J28: =IF(A28<>"", "_"&MONTH(A28)&"_", "") -> _4_
A29: 45758 | B29: Food & Drink | C29: Others | D29: 152 | E29: Mobile Banking | G29: 7-Eleven | I29: =IF(A29<>"", "_"&YEAR(A29)&"_", "") -> _2025_ | J29: =IF(A29<>"", "_"&MONTH(A29)&"_", "") -> _4_
A30: 45758 | B30: Transportation | C30: Fuel | D30: 1100.1 | E30: KTC Bangchak | F30: Credit Payment | G30: Bangchak | H30: น้ำมันกลับกาฬสินธุ์ | I30: =IF(A30<>"", "_"&YEAR(A30)&"_", "") -> _2025_ | J30: =IF(A30<>"", "_"&MONTH(A30)&"_", "") -> _4_
A31: 45759 | B31: Food & Drink | C31: Main meals | D31: 27 | E31: Mobile Banking | G31: 7-Eleven | H31: มาม่า | I31: =IF(A31<>"", "_"&YEAR(A31)&"_", "") -> _2025_ | J31: =IF(A31<>"", "_"&MONTH(A31)&"_", "") -> _4_
A32: 45759 | B32: Food & Drink | C32: Groceries | D32: 55 | E32: Mobile Banking | H32: ผลไม้ | I32: =IF(A32<>"", "_"&YEAR(A32)&"_", "") -> _2025_ | J32: =IF(A32<>"", "_"&MONTH(A32)&"_", "") -> _4_
A33: 45759 | B33: Food & Drink | C33: Snacks | D33: 160 | E33: Mobile Banking | H33: หมูกระจก | I33: =IF(A33<>"", "_"&YEAR(A33)&"_", "") -> _2025_ | J33: =IF(A33<>"", "_"&MONTH(A33)&"_", "") -> _4_
A34: 45759 | B34: Food & Drink | C34: Drinks | D34: 50 | E34: UOB One | F34: Credit Payment | G34: Amazon | H34: ชาเขียว | I34: =IF(A34<>"", "_"&YEAR(A34)&"_", "") -> _2025_ | J34: =IF(A34<>"", "_"&MONTH(A34)&"_", "") -> _4_
A35: 45759 | B35: Food & Drink | C35: Snacks | D35: 70 | E35: UOB One | F35: Credit Payment | I35: =IF(A35<>"", "_"&YEAR(A35)&"_", "") -> _2025_ | J35: =IF(A35<>"", "_"&MONTH(A35)&"_", "") -> _4_
A36: 45759 | B36: Others | C36: Family | D36: =1150.5-800 -> 350.5 | E36: UOB One | F36: Credit Payment | H36: ซื้อของฝากตายายย่า -1,150 | I36: =IF(A36<>"", "_"&YEAR(A36)&"_", "") -> _2025_ | J36: =IF(A36<>"", "_"&MONTH(A36)&"_", "") -> _4_
A37: 45759 | B37: Reimbursement | C37: Reimbursement | D37: =600+275.25 -> 875.25 | E37: UOB One | F37: Credit Payment | H37: แม่ + หมวยช่วยออก | I37: =IF(A37<>"", "_"&YEAR(A37)&"_", "") -> _2025_ | J37: =IF(A37<>"", "_"&MONTH(A37)&"_", "") -> _4_
A38: 45760 | B38: Food & Drink | C38: Main meals | D38: 236 | E38: UOB One | F38: Credit Payment | G38: KFC | I38: =IF(A38<>"", "_"&YEAR(A38)&"_", "") -> _2025_ | J38: =IF(A38<>"", "_"&MONTH(A38)&"_", "") -> _4_
A39: 45760 | B39: Food & Drink | C39: Snacks | D39: 138 | E39: UOB One | F39: Credit Payment | G39: Lotus | H39: Lotus Deli | I39: =IF(A39<>"", "_"&YEAR(A39)&"_", "") -> _2025_ | J39: =IF(A39<>"", "_"&MONTH(A39)&"_", "") -> _4_
A40: 45760 | B40: Food & Drink | C40: Main meals | D40: 139 | E40: UOB One | F40: Credit Payment | G40: KFC | I40: =IF(A40<>"", "_"&YEAR(A40)&"_", "") -> _2025_ | J40: =IF(A40<>"", "_"&MONTH(A40)&"_", "") -> _4_
...

Sheet Monthly Dashboard
A1: Year | B1: Month | C1: Category | F1: Sub-Category breakdown by Month
A2: _2025_ | B2: _10_ | C2: All | F2: =SUM('Background-Data'!H2:H240) -> 36303.43
F23: Remaining Balance | G23: =K25-E25 -> -36303.43
A25: EXPENSES | E25: =SUM(D44:D240) -> 36303.43 | H25: INCOME | K25: =SUM(J46:J240) -> 0
A45: =IFERROR(__xludf.DUMMYFUNCTION("QUERY(Transaction!A1:J240, ""SELECT A, B, C, D, G, H WHERE B != 'Monthly Pay' AND B != 'Investment' AND B != 'Reimbursement' AND I = '""&'Monthly Dashboard'!A2&""' AND J = '""&'Monthly Dashboard'!B2&""' ORDER BY A DESC"", 1)"),"Date") -> Date | B45: =IFERROR(__xludf.DUMMYFUNCTION("""COMPUTED_VALUE"""),"Category") -> Category | C45: =IFERROR(__xludf.DUMMYFUNCTION("""COMPUTED_VALUE"""),"Sub-Category") -> Sub-Category | D45: =IFERROR(__xludf.DUMMYFUNCTION("""COMPUTED_VALUE"""),"Amount") -> Amount | E45: =IFERROR(__xludf.DUMMYFUNCTION("""COMPUTED_VALUE"""),"Shop") -> Shop | F45: =IFERROR(__xludf.DUMMYFUNCTION("""COMPUTED_VALUE"""),"Note") -> Note | H45: =IFERROR(__xludf.DUMMYFUNCTION("QUERY(Transaction!A1:J240, ""SELECT A, C, D, H WHERE B = 'Monthly Pay' AND I = '""&'Monthly Dashboard'!A2&""' AND J = '""&'Monthly Dashboard'!B2&""' ORDER BY A DESC"", 1)"),"Date") -> Date | I45: =IFERROR(__xludf.DUMMYFUNCTION("""COMPUTED_VALUE"""),"Sub-Category") -> Sub-Category | J45: =IFERROR(__xludf.DUMMYFUNCTION("""COMPUTED_VALUE"""),"Amount") -> Amount | K45: =IFERROR(__xludf.DUMMYFUNCTION("""COMPUTED_VALUE"""),"Note") -> Note
A46: =IFERROR(__xludf.DUMMYFUNCTION("""COMPUTED_VALUE"""),45960.0) -> 45960 | B46: =IFERROR(__xludf.DUMMYFUNCTION("""COMPUTED_VALUE"""),"Food & Drink") -> Food & Drink | C46: =IFERROR(__xludf.DUMMYFUNCTION("""COMPUTED_VALUE"""),"Main meals") -> Main meals | D46: =IFERROR(__xludf.DUMMYFUNCTION("""COMPUTED_VALUE"""),372.0) -> 372 | E46: =IFERROR(__xludf.DUMMYFUNCTION("""COMPUTED_VALUE"""),"Pizza") -> Pizza
A47: =IFERROR(__xludf.DUMMYFUNCTION("""COMPUTED_VALUE"""),45959.0) -> 45959 | B47: =IFERROR(__xludf.DUMMYFUNCTION("""COMPUTED_VALUE"""),"Hobby") -> Hobby | C47: =IFERROR(__xludf.DUMMYFUNCTION("""COMPUTED_VALUE"""),"Education") -> Education | D47: =IFERROR(__xludf.DUMMYFUNCTION("""COMPUTED_VALUE"""),719.0) -> 719
A48: =IFERROR(__xludf.DUMMYFUNCTION("""COMPUTED_VALUE"""),45959.0) -> 45959 | B48: =IFERROR(__xludf.DUMMYFUNCTION("""COMPUTED_VALUE"""),"Food & Drink") -> Food & Drink | C48: =IFERROR(__xludf.DUMMYFUNCTION("""COMPUTED_VALUE"""),"Main meals") -> Main meals | D48: =IFERROR(__xludf.DUMMYFUNCTION("""COMPUTED_VALUE"""),50.0) -> 50 | E48: =IFERROR(__xludf.DUMMYFUNCTION("""COMPUTED_VALUE"""),"Hainanese chicken rice") -> Hainanese chicken rice
A49: =IFERROR(__xludf.DUMMYFUNCTION("""COMPUTED_VALUE"""),45959.0) -> 45959 | B49: =IFERROR(__xludf.DUMMYFUNCTION("""COMPUTED_VALUE"""),"Food & Drink") -> Food & Drink | C49: =IFERROR(__xludf.DUMMYFUNCTION("""COMPUTED_VALUE"""),"Snacks") -> Snacks | D49: =IFERROR(__xludf.DUMMYFUNCTION("""COMPUTED_VALUE"""),36.0) -> 36 | E49: =IFERROR(__xludf.DUMMYFUNCTION("""COMPUTED_VALUE"""),"CJ") -> CJ
A50: =IFERROR(__xludf.DUMMYFUNCTION("""COMPUTED_VALUE"""),45957.0) -> 45957 | B50: =IFERROR(__xludf.DUMMYFUNCTION("""COMPUTED_VALUE"""),"Transportation") -> Transportation | C50: =IFERROR(__xludf.DUMMYFUNCTION("""COMPUTED_VALUE"""),"Maintenance") -> Maintenance | D50: =IFERROR(__xludf.DUMMYFUNCTION("""COMPUTED_VALUE"""),1883.2) -> 1883.2 | F50: =IFERROR(__xludf.DUMMYFUNCTION("""COMPUTED_VALUE"""),"เข้าเช็คระยะ 63,000 km") -> เข้าเช็คระยะ 63,000 km
A51: =IFERROR(__xludf.DUMMYFUNCTION("""COMPUTED_VALUE"""),45957.0) -> 45957 | B51: =IFERROR(__xludf.DUMMYFUNCTION("""COMPUTED_VALUE"""),"Transportation") -> Transportation | C51: =IFERROR(__xludf.DUMMYFUNCTION("""COMPUTED_VALUE"""),"Fee") -> Fee | D51: =IFERROR(__xludf.DUMMYFUNCTION("""COMPUTED_VALUE"""),50.0) -> 50 | F51: =IFERROR(__xludf.DUMMYFUNCTION("""COMPUTED_VALUE"""),"ค่าจอดรถสนามบินส่งมิ้น") -> ค่าจอดรถสนามบินส่งมิ้น
A52: =IFERROR(__xludf.DUMMYFUNCTION("""COMPUTED_VALUE"""),45957.0) -> 45957 | B52: =IFERROR(__xludf.DUMMYFUNCTION("""COMPUTED_VALUE"""),"Food & Drink") -> Food & Drink | C52: =IFERROR(__xludf.DUMMYFUNCTION("""COMPUTED_VALUE"""),"Snacks") -> Snacks | D52: =IFERROR(__xludf.DUMMYFUNCTION("""COMPUTED_VALUE"""),204.0) -> 204 | E52: =IFERROR(__xludf.DUMMYFUNCTION("""COMPUTED_VALUE"""),"7-Eleven") -> 7-Eleven | F52: =IFERROR(__xludf.DUMMYFUNCTION("""COMPUTED_VALUE"""),"ตั้งแต่วันที่ 27-29") -> ตั้งแต่วันที่ 27-29
A53: =IFERROR(__xludf.DUMMYFUNCTION("""COMPUTED_VALUE"""),45956.0) -> 45956 | B53: =IFERROR(__xludf.DUMMYFUNCTION("""COMPUTED_VALUE"""),"Others") -> Others | C53: =IFERROR(__xludf.DUMMYFUNCTION("""COMPUTED_VALUE"""),"Others") -> Others | D53: =IFERROR(__xludf.DUMMYFUNCTION("""COMPUTED_VALUE"""),27.0) -> 27 | F53: =IFERROR(__xludf.DUMMYFUNCTION("""COMPUTED_VALUE"""),"ค่าส่งหูฟัง soundcore") -> ค่าส่งหูฟัง soundcore
A54: =IFERROR(__xludf.DUMMYFUNCTION("""COMPUTED_VALUE"""),45956.0) -> 45956 | B54: =IFERROR(__xludf.DUMMYFUNCTION("""COMPUTED_VALUE"""),"Food & Drink") -> Food & Drink | C54: =IFERROR(__xludf.DUMMYFUNCTION("""COMPUTED_VALUE"""),"Main meals") -> Main meals | D54: =IFERROR(__xludf.DUMMYFUNCTION("""COMPUTED_VALUE"""),85.0) -> 85 | E54: =IFERROR(__xludf.DUMMYFUNCTION("""COMPUTED_VALUE"""),"Noodle") -> Noodle
A55: =IFERROR(__xludf.DUMMYFUNCTION("""COMPUTED_VALUE"""),45956.0) -> 45956 | B55: =IFERROR(__xludf.DUMMYFUNCTION("""COMPUTED_VALUE"""),"Food & Drink") -> Food & Drink | C55: =IFERROR(__xludf.DUMMYFUNCTION("""COMPUTED_VALUE"""),"Drinks") -> Drinks | D55: =IFERROR(__xludf.DUMMYFUNCTION("""COMPUTED_VALUE"""),40.0) -> 40 | E55: =IFERROR(__xludf.DUMMYFUNCTION("""COMPUTED_VALUE"""),"CJ") -> CJ | F55: =IFERROR(__xludf.DUMMYFUNCTION("""COMPUTED_VALUE"""),"ชาไทย") -> ชาไทย
A56: =IFERROR(__xludf.DUMMYFUNCTION("""COMPUTED_VALUE"""),45956.0) -> 45956 | B56: =IFERROR(__xludf.DUMMYFUNCTION("""COMPUTED_VALUE"""),"Food & Drink") -> Food & Drink | C56: =IFERROR(__xludf.DUMMYFUNCTION("""COMPUTED_VALUE"""),"Groceries") -> Groceries | D56: =IFERROR(__xludf.DUMMYFUNCTION("""COMPUTED_VALUE"""),120.0) -> 120 | F56: =IFERROR(__xludf.DUMMYFUNCTION("""COMPUTED_VALUE"""),"ผัก") -> ผัก
A57: =IFERROR(__xludf.DUMMYFUNCTION("""COMPUTED_VALUE"""),45956.0) -> 45956 | B57: =IFERROR(__xludf.DUMMYFUNCTION("""COMPUTED_VALUE"""),"Transportation") -> Transportation | C57: =IFERROR(__xludf.DUMMYFUNCTION("""COMPUTED_VALUE"""),"Maintenance") -> Maintenance | D57: =IFERROR(__xludf.DUMMYFUNCTION("""COMPUTED_VALUE"""),1000.0) -> 1000 | F57: =IFERROR(__xludf.DUMMYFUNCTION("""COMPUTED_VALUE"""),"เปลี่ยนคิ้วรถ") -> เปลี่ยนคิ้วรถ
A58: =IFERROR(__xludf.DUMMYFUNCTION("""COMPUTED_VALUE"""),45955.0) -> 45955 | B58: =IFERROR(__xludf.DUMMYFUNCTION("""COMPUTED_VALUE"""),"Food & Drink") -> Food & Drink | C58: =IFERROR(__xludf.DUMMYFUNCTION("""COMPUTED_VALUE"""),"Main meals") -> Main meals | D58: =IFERROR(__xludf.DUMMYFUNCTION("""COMPUTED_VALUE"""),80.0) -> 80 | F58: =IFERROR(__xludf.DUMMYFUNCTION("""COMPUTED_VALUE"""),"กะเพรา") -> กะเพรา
A59: =IFERROR(__xludf.DUMMYFUNCTION("""COMPUTED_VALUE"""),45955.0) -> 45955 | B59: =IFERROR(__xludf.DUMMYFUNCTION("""COMPUTED_VALUE"""),"Food & Drink") -> Food & Drink | C59: =IFERROR(__xludf.DUMMYFUNCTION("""COMPUTED_VALUE"""),"Groceries") -> Groceries | D59: =IFERROR(__xludf.DUMMYFUNCTION("""COMPUTED_VALUE"""),162.0) -> 162 | F59: =IFERROR(__xludf.DUMMYFUNCTION("""COMPUTED_VALUE"""),"ผัก") -> ผัก
A60: =IFERROR(__xludf.DUMMYFUNCTION("""COMPUTED_VALUE"""),45955.0) -> 45955 | B60: =IFERROR(__xludf.DUMMYFUNCTION("""COMPUTED_VALUE"""),"Food & Drink") -> Food & Drink | C60: =IFERROR(__xludf.DUMMYFUNCTION("""COMPUTED_VALUE"""),"Drinks") -> Drinks | D60: =IFERROR(__xludf.DUMMYFUNCTION("""COMPUTED_VALUE"""),40.0) -> 40 | E60: =IFERROR(__xludf.DUMMYFUNCTION("""COMPUTED_VALUE"""),"CJ") -> CJ | F60: =IFERROR(__xludf.DUMMYFUNCTION("""COMPUTED_VALUE"""),"ชาไทย") -> ชาไทย
A61: =IFERROR(__xludf.DUMMYFUNCTION("""COMPUTED_VALUE"""),45955.0) -> 45955 | B61: =IFERROR(__xludf.DUMMYFUNCTION("""COMPUTED_VALUE"""),"Items") -> Items | C61: =IFERROR(__xludf.DUMMYFUNCTION("""COMPUTED_VALUE"""),"Household Items") -> Household Items | D61: =IFERROR(__xludf.DUMMYFUNCTION("""COMPUTED_VALUE"""),142.0) -> 142 | E61: =IFERROR(__xludf.DUMMYFUNCTION("""COMPUTED_VALUE"""),"Lotus") -> Lotus | F61: =IFERROR(__xludf.DUMMYFUNCTION("""COMPUTED_VALUE"""),"สำลี ครีมอาบน้ำไ") -> สำลี ครีมอาบน้ำไ
A62: =IFERROR(__xludf.DUMMYFUNCTION("""COMPUTED_VALUE"""),45955.0) -> 45955 | B62: =IFERROR(__xludf.DUMMYFUNCTION("""COMPUTED_VALUE"""),"Food & Drink") -> Food & Drink | C62: =IFERROR(__xludf.DUMMYFUNCTION("""COMPUTED_VALUE"""),"Groceries") -> Groceries | D62: =IFERROR(__xludf.DUMMYFUNCTION("""COMPUTED_VALUE"""),381.25) -> 381.25 | E62: =IFERROR(__xludf.DUMMYFUNCTION("""COMPUTED_VALUE"""),"Lotus") -> Lotus
A63: =IFERROR(__xludf.DUMMYFUNCTION("""COMPUTED_VALUE"""),45954.0) -> 45954 | B63: =IFERROR(__xludf.DUMMYFUNCTION("""COMPUTED_VALUE"""),"Others") -> Others | C63: =IFERROR(__xludf.DUMMYFUNCTION("""COMPUTED_VALUE"""),"Debt") -> Debt | D63: =IFERROR(__xludf.DUMMYFUNCTION("""COMPUTED_VALUE"""),8521.0) -> 8521 | F63: =IFERROR(__xludf.DUMMYFUNCTION("""COMPUTED_VALUE"""),"ค่ารถงวด 39") -> ค่ารถงวด 39
A64: =IFERROR(__xludf.DUMMYFUNCTION("""COMPUTED_VALUE"""),45954.0) -> 45954 | B64: =IFERROR(__xludf.DUMMYFUNCTION("""COMPUTED_VALUE"""),"Others") -> Others | C64: =IFERROR(__xludf.DUMMYFUNCTION("""COMPUTED_VALUE"""),"Devidend") -> Devidend | D64: =IFERROR(__xludf.DUMMYFUNCTION("""COMPUTED_VALUE"""),2000.0) -> 2000 | E64: =IFERROR(__xludf.DUMMYFUNCTION("""COMPUTED_VALUE"""),"Studentloan Debt") -> Studentloan Debt | F64: =IFERROR(__xludf.DUMMYFUNCTION("""COMPUTED_VALUE"""),"กยศ") -> กยศ
A65: =IFERROR(__xludf.DUMMYFUNCTION("""COMPUTED_VALUE"""),45954.0) -> 45954 | B65: =IFERROR(__xludf.DUMMYFUNCTION("""COMPUTED_VALUE"""),"Service") -> Service | C65: =IFERROR(__xludf.DUMMYFUNCTION("""COMPUTED_VALUE"""),"Home Internet") -> Home Internet | D65: =IFERROR(__xludf.DUMMYFUNCTION("""COMPUTED_VALUE"""),650.0) -> 650 | F65: =IFERROR(__xludf.DUMMYFUNCTION("""COMPUTED_VALUE"""),"เน็ตบ้าน") -> เน็ตบ้าน
A66: =IFERROR(__xludf.DUMMYFUNCTION("""COMPUTED_VALUE"""),45954.0) -> 45954 | B66: =IFERROR(__xludf.DUMMYFUNCTION("""COMPUTED_VALUE"""),"Service") -> Service | C66: =IFERROR(__xludf.DUMMYFUNCTION("""COMPUTED_VALUE"""),"Mobile Internet") -> Mobile Internet | D66: =IFERROR(__xludf.DUMMYFUNCTION("""COMPUTED_VALUE"""),450.0) -> 450 | F66: =IFERROR(__xludf.DUMMYFUNCTION("""COMPUTED_VALUE"""),"เน็็ตมือถือ") -> เน็็ตมือถือ
A67: =IFERROR(__xludf.DUMMYFUNCTION("""COMPUTED_VALUE"""),45954.0) -> 45954 | B67: =IFERROR(__xludf.DUMMYFUNCTION("""COMPUTED_VALUE"""),"Food & Drink") -> Food & Drink | C67: =IFERROR(__xludf.DUMMYFUNCTION("""COMPUTED_VALUE"""),"Main meals") -> Main meals | D67: =IFERROR(__xludf.DUMMYFUNCTION("""COMPUTED_VALUE"""),80.0) -> 80 | F67: =IFERROR(__xludf.DUMMYFUNCTION("""COMPUTED_VALUE"""),"ข้าวมันไก่, ลูกชิ้น") -> ข้าวมันไก่, ลูกชิ้น
A68: =IFERROR(__xludf.DUMMYFUNCTION("""COMPUTED_VALUE"""),45954.0) -> 45954 | B68: =IFERROR(__xludf.DUMMYFUNCTION("""COMPUTED_VALUE"""),"Food & Drink") -> Food & Drink | C68: =IFERROR(__xludf.DUMMYFUNCTION("""COMPUTED_VALUE"""),"Main meals") -> Main meals | D68: =IFERROR(__xludf.DUMMYFUNCTION("""COMPUTED_VALUE"""),190.0) -> 190 | E68: =IFERROR(__xludf.DUMMYFUNCTION("""COMPUTED_VALUE"""),"Bonchon") -> Bonchon
A69: =IFERROR(__xludf.DUMMYFUNCTION("""COMPUTED_VALUE"""),45953.0) -> 45953 | B69: =IFERROR(__xludf.DUMMYFUNCTION("""COMPUTED_VALUE"""),"Food & Drink") -> Food & Drink | C69: =IFERROR(__xludf.DUMMYFUNCTION("""COMPUTED_VALUE"""),"Snacks") -> Snacks | D69: =IFERROR(__xludf.DUMMYFUNCTION("""COMPUTED_VALUE"""),37.0) -> 37 | F69: =IFERROR(__xludf.DUMMYFUNCTION("""COMPUTED_VALUE"""),"โตเกียว") -> โตเกียว
A70: =IFERROR(__xludf.DUMMYFUNCTION("""COMPUTED_VALUE"""),45952.0) -> 45952 | B70: =IFERROR(__xludf.DUMMYFUNCTION("""COMPUTED_VALUE"""),"Food & Drink") -> Food & Drink | C70: =IFERROR(__xludf.DUMMYFUNCTION("""COMPUTED_VALUE"""),"Main meals") -> Main meals | D70: =IFERROR(__xludf.DUMMYFUNCTION("""COMPUTED_VALUE"""),153.0) -> 153 | E70: =IFERROR(__xludf.DUMMYFUNCTION("""COMPUTED_VALUE"""),"KFC") -> KFC
A71: =IFERROR(__xludf.DUMMYFUNCTION("""COMPUTED_VALUE"""),45952.0) -> 45952 | B71: =IFERROR(__xludf.DUMMYFUNCTION("""COMPUTED_VALUE"""),"Others") -> Others | C71: =IFERROR(__xludf.DUMMYFUNCTION("""COMPUTED_VALUE"""),"Others") -> Others | D71: =IFERROR(__xludf.DUMMYFUNCTION("""COMPUTED_VALUE"""),100.0) -> 100 | F71: =IFERROR(__xludf.DUMMYFUNCTION("""COMPUTED_VALUE"""),"ให้พาย") -> ให้พาย
A72: =IFERROR(__xludf.DUMMYFUNCTION("""COMPUTED_VALUE"""),45951.0) -> 45951 | B72: =IFERROR(__xludf.DUMMYFUNCTION("""COMPUTED_VALUE"""),"Food & Drink") -> Food & Drink | C72: =IFERROR(__xludf.DUMMYFUNCTION("""COMPUTED_VALUE"""),"Main meals") -> Main meals | D72: =IFERROR(__xludf.DUMMYFUNCTION("""COMPUTED_VALUE"""),139.0) -> 139 | E72: =IFERROR(__xludf.DUMMYFUNCTION("""COMPUTED_VALUE"""),"Noodle") -> Noodle | F72: =IFERROR(__xludf.DUMMYFUNCTION("""COMPUTED_VALUE"""),"เตี๋ยวไก่") -> เตี๋ยวไก่
A73: =IFERROR(__xludf.DUMMYFUNCTION("""COMPUTED_VALUE"""),45950.0) -> 45950 | B73: =IFERROR(__xludf.DUMMYFUNCTION("""COMPUTED_VALUE"""),"Food & Drink") -> Food & Drink | C73: =IFERROR(__xludf.DUMMYFUNCTION("""COMPUTED_VALUE"""),"Main meals") -> Main meals | D73: =IFERROR(__xludf.DUMMYFUNCTION("""COMPUTED_VALUE"""),85.0) -> 85 | F73: =IFERROR(__xludf.DUMMYFUNCTION("""COMPUTED_VALUE"""),"กะเพรา") -> กะเพรา
A74: =IFERROR(__xludf.DUMMYFUNCTION("""COMPUTED_VALUE"""),45950.0) -> 45950 | B74: =IFERROR(__xludf.DUMMYFUNCTION("""COMPUTED_VALUE"""),"Food & Drink") -> Food & Drink | C74: =IFERROR(__xludf.DUMMYFUNCTION("""COMPUTED_VALUE"""),"Dine-out") -> Dine-out | D74: =IFERROR(__xludf.DUMMYFUNCTION("""COMPUTED_VALUE"""),534.0) -> 534 | F74: =IFERROR(__xludf.DUMMYFUNCTION("""COMPUTED_VALUE"""),"BBQ Plaza") -> BBQ Plaza
A75: =IFERROR(__xludf.DUMMYFUNCTION("""COMPUTED_VALUE"""),45950.0) -> 45950 | B75: =IFERROR(__xludf.DUMMYFUNCTION("""COMPUTED_VALUE"""),"Food & Drink") -> Food & Drink | C75: =IFERROR(__xludf.DUMMYFUNCTION("""COMPUTED_VALUE"""),"Snacks") -> Snacks | D75: =IFERROR(__xludf.DUMMYFUNCTION("""COMPUTED_VALUE"""),10.0) -> 10 | F75: =IFERROR(__xludf.DUMMYFUNCTION("""COMPUTED_VALUE"""),"ถั่ว") -> ถั่ว
A76: =IFERROR(__xludf.DUMMYFUNCTION("""COMPUTED_VALUE"""),45950.0) -> 45950 | B76: =IFERROR(__xludf.DUMMYFUNCTION("""COMPUTED_VALUE"""),"Residence") -> Residence | C76: =IFERROR(__xludf.DUMMYFUNCTION("""COMPUTED_VALUE"""),"Water Bill") -> Water Bill | D76: =IFERROR(__xludf.DUMMYFUNCTION("""COMPUTED_VALUE"""),184.07) -> 184.07 | F76: =IFERROR(__xludf.DUMMYFUNCTION("""COMPUTED_VALUE"""),"ค่าน้ำ") -> ค่าน้ำ
A77: =IFERROR(__xludf.DUMMYFUNCTION("""COMPUTED_VALUE"""),45950.0) -> 45950 | B77: =IFERROR(__xludf.DUMMYFUNCTION("""COMPUTED_VALUE"""),"Food & Drink") -> Food & Drink | C77: =IFERROR(__xludf.DUMMYFUNCTION("""COMPUTED_VALUE"""),"Snacks") -> Snacks | D77: =IFERROR(__xludf.DUMMYFUNCTION("""COMPUTED_VALUE"""),278.0) -> 278 | E77: =IFERROR(__xludf.DUMMYFUNCTION("""COMPUTED_VALUE"""),"7-Eleven") -> 7-Eleven | F77: =IFERROR(__xludf.DUMMYFUNCTION("""COMPUTED_VALUE"""),"ตั้งแต่วันที่ 20-24") -> ตั้งแต่วันที่ 20-24
A78: =IFERROR(__xludf.DUMMYFUNCTION("""COMPUTED_VALUE"""),45949.0) -> 45949 | B78: =IFERROR(__xludf.DUMMYFUNCTION("""COMPUTED_VALUE"""),"Service") -> Service | C78: =IFERROR(__xludf.DUMMYFUNCTION("""COMPUTED_VALUE"""),"Subscription") -> Subscription | D78: =IFERROR(__xludf.DUMMYFUNCTION("""COMPUTED_VALUE"""),1200.0) -> 1200 | F78: =IFERROR(__xludf.DUMMYFUNCTION("""COMPUTED_VALUE"""),"เข้ากลุ่มลิงเล่นหุ้นรายปี") -> เข้ากลุ่มลิงเล่นหุ้นรายปี
A79: =IFERROR(__xludf.DUMMYFUNCTION("""COMPUTED_VALUE"""),45949.0) -> 45949 | B79: =IFERROR(__xludf.DUMMYFUNCTION("""COMPUTED_VALUE"""),"Food & Drink") -> Food & Drink | C79: =IFERROR(__xludf.DUMMYFUNCTION("""COMPUTED_VALUE"""),"Groceries") -> Groceries | D79: =IFERROR(__xludf.DUMMYFUNCTION("""COMPUTED_VALUE"""),60.0) -> 60 | F79: =IFERROR(__xludf.DUMMYFUNCTION("""COMPUTED_VALUE"""),"ผักตลาด") -> ผักตลาด
A80: =IFERROR(__xludf.DUMMYFUNCTION("""COMPUTED_VALUE"""),45949.0) -> 45949 | B80: =IFERROR(__xludf.DUMMYFUNCTION("""COMPUTED_VALUE"""),"Food & Drink") -> Food & Drink | C80: =IFERROR(__xludf.DUMMYFUNCTION("""COMPUTED_VALUE"""),"Snacks") -> Snacks | D80: =IFERROR(__xludf.DUMMYFUNCTION("""COMPUTED_VALUE"""),99.0) -> 99 | F80: =IFERROR(__xludf.DUMMYFUNCTION("""COMPUTED_VALUE"""),"bing su") -> bing su
...

Sheet Credit Installment
A1: ID | B1: Start Date | C1: Card | D1: Item | E1: Amount | F1: Installments | G1: Paid Months | H1: Monthly Pay | I1: Remaining | J1: End Date | K1: Note
A2: =IF(B2<>"", IFERROR(A1+1, 1),"") -> 1 | B2: 45780 | C2: KTC Bangchak | D2: ยาง BS_Turanza_6 (53,200km) | E2: 14560 | F2: 10 | G2: 10 | H2: =E2/F2 -> 1456 | I2: =E2-(G2*H2) -> 0 | J2: =EDATE(B2,F2-1) -> 46056 | K2: จ่ายครั้งที่ 10 - 09/02/2026
A3: =IF(B3<>"", IFERROR(A2+1, 1),"") -> 2 | B3: 45870 | C3: TTB So Smart | D3: Googl One AI | E3: 7500 | F3: 3 | G3: 3 | H3: =E3/F3 -> 2500 | I3: =E3-(G3*H3) -> 0 | J3: =EDATE(B3,F3-1) -> 45931 | K3: จ่ายครั้งที่ 3 - 02/10/2025
A4: =IF(B4<>"", IFERROR(A3+1, 1),"") -> 3 | B4: 46062 | C4: KTC Bangchak | D4: แว่นตา Owndays | E4: 15560 | F4: 4 | G4: 4 | H4: =E4/F4 -> 3890 | I4: =E4-(G4*H4) -> 0 | J4: =EDATE(B4,F4-1) -> 46151 | K4: จ่ายครั้งที่ 4 - 07/05/2026
A5: =IF(B5<>"", IFERROR(A4+1, 1),"") -> 4 | B5: 46056 | C5: TTB So Smart | D5: IPhone 17 Pro | E5: 38800 | F5: 10 | G5: 4 | H5: =E5/F5 -> 3880 | I5: =E5-(G5*H5) -> 23280 | J5: =EDATE(B5,F5-1) -> 46329 | K5: จ่ายครั้งที่ 4 - 01/06/2026
A6: =IF(B6<>"", IFERROR(A5+1, 1),"") -> 5 | B6: 46145 | C6: UOB One | D6: ช่วงล่าง Mu-X ที Auto 1 | E6: 24725.25 | F6: 10 | G6: 1 | H6: =E6/F6 -> 2472.525 | I6: =E6-(G6*H6) -> 22252.725 | J6: =EDATE(B6,F6-1) -> 46421 | K6: จ่ายครั้งที่ 1 - 18/05/2026
A7: =IF(B7<>"", IFERROR(A6+1, 1),"")
A8: =IF(B8<>"", IFERROR(A7+1, 1),"")
A9: =IF(B9<>"", IFERROR(A8+1, 1),"")
A10: =IF(B10<>"", IFERROR(A9+1, 1),"")
A11: =IF(B11<>"", IFERROR(A10+1, 1),"")
A12: =IF(B12<>"", IFERROR(A11+1, 1),"")
A13: =IF(B13<>"", IFERROR(A12+1, 1),"")
A14: =IF(B14<>"", IFERROR(A13+1, 1),"")
A15: =IF(B15<>"", IFERROR(A14+1, 1),"")
A16: =IF(B16<>"", IFERROR(A15+1, 1),"")
A17: =IF(B17<>"", IFERROR(A16+1, 1),"")
A18: =IF(B18<>"", IFERROR(A17+1, 1),"")
... A120: =IF(B120<>"", IFERROR(A119+1, 1),"")

Sheet Monthly Plan
A1: กิน | B1: 8400 | C1: 8400 | D1: 8400 | E1: 8400 | F1: Income | G1: หมายเหตุ
F2: =sum(26000+10000+4950+2657+1600+6332)-(2562.14+689-657)-125-1026.64 -> 47793.22
A3: ค่าของเข้าห้อง/บ้าน mbk | B3: 250 | C3: 250 | D3: 250 | E3: 250
G4: หัก Tax 900 -> 1,000
A5: ค่าน้ำมัน(เดินทาง) mbk | B5: 3000 | C5: 3000 | D5: 3000 | E5: 3000 | G5: เป้าหมายเงินฉุกเฉิน 25,000*6=150,000
A7: น้ำไฟ mbk | B7: 1500 | C7: 1500 | D7: 1500 | E7: 1500
A9: ค่ารถ nombk | B9: 8251 | C9: 8251 | D9: 8251 | E9: 8251
A11: skincare mbk | B11: 700 | C11: 700 | D11: 700 | E11: 700
A13: ค่าเน็ต AIS | B13: 1100 | C13: 1100 | D13: 1100 | E13: 1100
A14: YT Premium | B14: 50 | C14: 50 | D14: 50 | E14: 50
A15: SUM | B15: =SUM(B1:B14) -> 23251 | C15: =SUM(C1:C14) -> 23251 | D15: =SUM(D1:D14) -> 23251 | E15: =SUM(E1:E14) -> 23251
B17: Current case | C17: July | D17: Nov | E17: ปี 2027
B18: =SUM(F2-B15) -> 24542.22 | C18: =SUM(F2-C15) -> 24542.22 | D18: =SUM(F2-D15) -> 24542.22 | E18: =SUM(F2-E15) -> 24542.22
A20: เงินที่เหลือจากข้างบน | B20: =B18 -> 24542.22 | C20: =C18 -> 24542.22 | D20: =D18 -> 24542.22 | E20: =E18 -> 24542.22 | G20: ของเข้าบ้านเดี๋ยวใส่เพิ่มเดือน 4/2026
A21: free เอาไปใส่ได้หมด | B21: =SUM(B22:B32)-B20 -> 0 | C21: =SUM(C22:C32)-C20 -> 0 | D21: =SUM(D22:D32)-D20 -> 0 | E21: =SUM(E22:E32)-E20 -> 0
A22: ผ่อน IP 17Pro | B22: 3880 | C22: 3880 | H22: เช่นเก็บ 3,000 แต่เงินถึง 30k แล้วให้หักไป 2k ไปจ่าย กยศ
A23: เที่ยว, กิน kept | B23: 7112.22 | C23: 5000 | D23: 2000 | E23: 4000
A24: ภาษี kept | B24: 800 | C24: 500 | D24: 500 | E24: 600
A25: เงินฉุกเฉิน kept | B25: 5000 | C25: 10412.22 | D25: 17292.22 | E25: 15192.22
A26: กยศ dime | B26: 3000 | C26: 0 | D26: 0 | E26: 0 | G26: เดือนกรกฎาเก็บไว้ใน kept จนกว่าจะครบยอดผ่อนปี 2670
A27: รถยนต์ kept | B27: 2000 | C27: 2000 | D27: 2000 | E27: 2000
A28: รอเทรดหุ้น dime | B28: 0 | E28: 0
A29: Gemini kept | B29: 750 | C29: 750 | D29: 750 | E29: 750
A30: ประกันรวม kept | B30: 2000 | C30: 2000 | D30: 2000 | E30: 2000
A33: รวม | B33: =SUM(B22:B32) -> 24542.22 | C33: =SUM(C22:C32) -> 24542.22 | D33: =SUM(D22:D32) -> 24542.22 | E33: =SUM(E22:E32) -> 24542.22
G34: ถ้าเงินเก็บ > 100k เอามาผ่อน กยศ
A37: ยอด OT | B37: ฉุกเฉิน 25% | C37: ไว้เทรด 30% | D37: ภาษี 15% | E37: อะไรก็ได้ 30%
A38: 1000 | B38: =A38*25% -> 250 | C38: =A38*30% -> 300 | D38: =A38*15% -> 150 | E38: =A38*30% -> 300
A44: แผน Bonus ปี 2027
A45: รถ
A46: เติม us stock | C46: ดูว่าเหลืออีกเท่าไหร่ก็หักออกไปได้เลย
A47: เงินฉุกเฉิน | B47: 20000
A48: เปย์ตัวเอง | B48: 30000 | C48: ถ้าเงิน travel ไม่ถึง 30k ก็เติมเข้าไป
A49: ซื้อของเข้าบ้าน | B49: 16000 | C49: รวมจ่ายค่าส่วนกลางหมู่บ้าน
A50: กยศ | B50: 30000 | C50: รอจ่ายตอนยอดของปีขึ้นมา
A51: กยศ จ่ายเลย | B51: 9000
A52: ซื้อของใหญ่ | B52: 15000
A54: รวม | B54: =SUM(B45:B52) -> 120000
A55: Bonus | B55: 120000
A56: คงเหลือ | B56: =B55-B54 -> 0 | C56: ให้ย่า
...

Sheet Overall
A1: Summary
A2: List | B2: 2024 | C2: =C19 -> 95572.28 | D2: 2026 | E2: 2027 | F2: 2028 | G2: 2029 | H2: 2030
A3: Contigency reserve | B3: =B19 -> 83753.74 | C3: =C19 -> 95572.28 | D3: =D19 -> 109380.12
A4: Hold for pay | B4: =B34 -> 121535.29 | C4: =C34 -> 129744.98 | D4: =D34 -> 70404.37
A7: Sum only KEPT | B7: =B14+B34 -> 193968.77 | C7: =C14 + C34 -> 219375.57 | D7: =D14 + D34 -> 168784.49
A8: All Networth | B8: =SUM(B3:B5) -> 205289.03 | C8: =SUM(C3:C5) -> 225317.26 | D8: =SUM(D3:D5) -> 179784.49
A11: Contigency Reserve
A12: Contigency | B12: 2024(50k) | C12: 2025 (80k) | D12: 2026 (100k) | E12: 2027 (120k) | F12: 2028 (140k) | G12: 2029 (160k) | H12: 2030 (200K)
A13: Make by kbank | B13: 262.27 | C13: 1000 | D13: =SUM(C13, SUMIF('Contigency Reserve'!C:C, "mbk_2026", 'Contigency Reserve'!D:D) - SUMIF('Contigency Reserve'!C:C, "mbk_2026", 'Contigency Reserve'!E:E) + SUMIF('Contigency Reserve'!C:C, "mbk_2026", 'Contigency Reserve'!F:F)) -> 1000
A14: Kept by krungsri | B14: 72433.48 | C14: 89630.59 | D14: =SUM(C14, SUMIF('Contigency Reserve'!C:C, "kept_2026", 'Contigency Reserve'!D:D) - SUMIF('Contigency Reserve'!C:C, "kept_2026", 'Contigency Reserve'!E:E) + SUMIF('Contigency Reserve'!C:C, "kept_2026", 'Contigency Reserve'!F:F)) -> 98380.12
A15: Bualuang bank (balance) | B15: 1057.99 | C15: =SUM(B15, SUMIF('Contigency Reserve'!C:D, "blb_2025", 'Contigency Reserve'!D:D) - SUMIF('Contigency Reserve'!C:D, "blb_2025", 'Contigency Reserve'!E:E) + SUMIF('Contigency Reserve'!C:D, "blb_2025", 'Contigency Reserve'!F:F)) -> 1000 | D15: =SUM(C15, SUMIF('Contigency Reserve'!C:C, "blb_2026", 'Contigency Reserve'!D:D) - SUMIF('Contigency Reserve'!C:C, "blb_2026", 'Contigency Reserve'!E:E) + SUMIF('Contigency Reserve'!C:C, "blb_2026", 'Contigency Reserve'!F:F)) -> 0
A16: Dime | B16: 10000 | C16: 3941.69 | D16: =SUM(C16, SUMIF('Contigency Reserve'!C:C, "dime_2026", 'Contigency Reserve'!D:D) - SUMIF('Contigency Reserve'!C:C, "dime_2026", 'Contigency Reserve'!E:E) + SUMIF('Contigency Reserve'!C:C, "dime_2026", 'Contigency Reserve'!F:F)) -> 10000
A19: Sum | B19: =SUM(B13:B18) -> 83753.74 | C19: =SUM(C13:C18) -> 95572.28 | D19: =SUM(D13:D18) -> 109380.12
A22: Hold for pay
A23: Hold for pay (kept) | B23: 2024 | C23: 2025 | D23: 2026 | E23: 2027 | F23: 2028 | G23: 2029 | H23: 2030
A24: Tax | B24: 22260.01 | C24: 17340.06 | D24: =SUM(C24,SUMIF('Hold for pay'!C:C, "tax_2026", 'Hold for pay'!D:D)-SUMIF('Hold for pay'!C:C, "tax_2026", 'Hold for pay'!E:E)) -> 13008.06
A25: Studentloan | B25: 6000 | C25: 8000 | D25: =SUM(C25,SUMIF('Hold for pay'!C:C, "sl_2026", 'Hold for pay'!D:D)-SUMIF('Hold for pay'!C:C, "sl_2026", 'Hold for pay'!E:E)) -> 8000 | I25: ปิดหนี้ กรอ เดือน 1 ปี 2028
A26: Travel | B26: 32084.6 | C26: 30736.87 | D26: =SUM(C26,SUMIF('Hold for pay'!C:C, "travel_2026", 'Hold for pay'!D:D)-SUMIF('Hold for pay'!C:C, "travel_2026", 'Hold for pay'!E:E)) -> 11364.81
A27: Car | B27: 35665.17 | C27: 24601.97 | D27: =SUM(C27,SUMIF('Hold for pay'!C:C, "car_2026", 'Hold for pay'!D:D)-SUMIF('Hold for pay'!C:C, "car_2026", 'Hold for pay'!E:E)) -> 14789.32
A28: Buy big thing | B28: 25525.51 | C28: 43068.08 | D28: =SUM(C28,SUMIF('Hold for pay'!C:C, "bigthin_2026", 'Hold for pay'!D:D)-SUMIF('Hold for pay'!C:C, "bigthin_2026", 'Hold for pay'!E:E)) -> 3494.18 | I28: เดือน august เอาเงินนี้ไปผ่อน
A29: Learn | B29: 0 | C29: 284 | D29: =SUM(C29,SUMIF('Hold for pay'!C:C, "learn_2026", 'Hold for pay'!D:D)-SUMIF('Hold for pay'!C:C, "learn_2026", 'Hold for pay'!E:E)) -> 284
A30: Insure | B30: 0 | C30: 1964 | D30: =SUM(C30,SUMIF('Hold for pay'!C:C, "insure_2026", 'Hold for pay'!D:D)-SUMIF('Hold for pay'!C:C, "insure_2026", 'Hold for pay'!E:E)) -> 11964
A31: Subscribe | B31: 0 | C31: 3750 | D31: =SUM(C31,SUMIF('Hold for pay'!C:C, "sub_2026", 'Hold for pay'!D:D)-SUMIF('Hold for pay'!C:C, "sub_2026", 'Hold for pay'!E:E)) -> 7500
A34: Sum | B34: =SUM(B24:B33) -> 121535.29 | C34: =SUM(C24:C33) -> 129744.98 | D34: =SUM(D24:D33) -> 70404.37

Sheet Hold for pay
A1: List | B1: Date | C1: To | D1: Deposit | E1: Withdraw | G1: Card
A6: case, phone gear | B6: 46186 | C6: travel_2026 | F6: 354 | G6: uob
A7: ประกันรถยนต์ | B7: 46187 | C7: car_2026 | E7: 12808
A8: pepsi can, milk, yogurt | B8: 46183 | C8: travel_2026 | E8: 429 | F8: 429 | G8: uob
A9: wheyprotein, honey, ไขควง | B9: 46183 | C9: travel_2026 | F9: 792 | G9: ttb
A10: Davinci course for video editing. | B10: 46179 | C10: travel_2026 | E10: 509 | F10: 509 | G10: uob
A11: case ip17pro, whey protein, doll, fragrance | B11: 46178 | C11: travel_2026 | F11: 1379 | G11: ttb
A12: แคปหมู, film ip, pepsi, phone strap | B12: 46176 | C12: travel_2026 | E12: 1074.91 | F12: 1074.91 | G12: uob
A13: ยาสีฟัน, case ip17pro, phone holder, shokubutsu | B13: 46176 | C13: travel_2026 | E13: 1153 | F13: 1153 | G13: uob
A14: พักรอจ่ายค่าซ่อมรถแม่(จ่าย) | B14: 46176 | C14: travel_2026 | D14: 2000 | E14: 2000
A15: ภาษี | B15: 46176 | C15: tax_2026 | D15: 427
A16: กาแฟ | B16: 46176 | C16: travel_2026 | E16: 145
A17: ข้าวเที่ยงกับไอเก๋า | B17: 46176 | C17: travel_2026 | E17: 225
A18: เบียร์ลาดพร้าว | B18: 46176 | C18: travel_2026 | E18: 557
A19: จ่ายภาษี 3/3 | B19: 46174 | C19: tax_2026 | E19: 4388
A20: ภาษี | B20: 46168 | C20: tax_2026 | D20: 570
A21: รอจ่ายของเข้าบ้าน | B21: 46168 | C21: travel_2026 | D21: 2222 | F21: 2222 ถึงวันค่อยหัก | G21: ttb
A22: health insure | B22: 46167 | C22: insure_2026 | D22: 2000
A23: google one ai | B23: 46167 | C23: sub_2026 | D23: 750
A24: รถยนต์ | B24: 46167 | C24: car_2026 | D24: 2000
A25: ภาษีี | B25: 46167 | C25: tax_2026 | D25: 800
A26: กินเที่ยว | B26: 46167 | C26: travel_2026 | D26: 7112.22
A27: ซื้อของฝากปั๊มเท่ง | B27: 46163 | C27: travel_2026 | E27: 389
A28: ค่าเที่ี่ยว | B28: 46164 | C28: travel_2026 | E28: 1000
A29: เติมน้ำมัันเพชรบุรี | B29: 46163 | C29: travel_2026 | E29: 1000
A30: เติมน้ำมันละแม ชุมพร | B30: 46162 | C30: travel_2026 | E30: 1000
A31: เติมน้ำมันที่สุราษ | B31: 46160 | C31: travel_2026 | E31: 1000
A32: ค่าน้ำมันขากลับ | B32: 46162 | C32: travel_2026 | E32: 1000
A33: Old spice & Ulanzi SC-02, ตาข่าย Mu-X | B33: 46163 | C33: travel_2026 | F33: 2232 มียกเลิกไป 351 = 1881 | G33: ttb
A34: ค่ากิินเที่ยว | B34: 46163 | C34: travel_2026 | E34: 1000
A35: ค่าไข่เค็มของฝาก | B35: 46162 | C35: travel_2026 | E35: 300
A36: ค่าเบียร์ร้านพี่มน | B36: 46162 | C36: travel_2026 | E36: 370
A37: ค่าเหล้าวิถี On Tap | B37: 46161 | C37: travel_2026 | E37: 770
A38: ค่าห้องพัก | B38: 46161 | C38: travel_2026 | E38: 420
A39: จ่ายค่าซ่อมรถแม่เพิ่ม | B39: 46160 | C39: travel_2026 | E39: =236.89+110 -> 346.89
A40: ค่าเน็ต ais | B40: 46160 | C40: travel_2026 | E40: 900
A41: ค่ากินเที่ยว | B41: 46159 | C41: travel_2026 | E41: 2000
A42: ค่าแคมป์วังปริง+เข้า อทย | B42: 46158 | C42: travel_2026 | E42: 250
A43: ค่าที่ี่พัก smile resort ทุ่งสง | B43: 46153 | C43: travel_2026 | E43: 590
A44: น้ำมันก่อนเข้าทุ่งสง | B44: 46153 | C44: travel_2026 | E44: 1000
...

Sheet Contigency Reserve
A1: List | B1: Date | C1: To | D1: Deposit | E1: Withdraw | F1: Interest
A6: เติมหุ้น | B6: 46185 | C6: kept_2026 | E6: 10000
A7: ฝากเงิน | B7: 46174 | C7: kept_2026 | D7: 1508.6
A8: ดอกเบี้ย kept | B8: 46170 | C8: kept_2026 | F8: 248.91
A9: ttb ss cashback | B9: 46167 | C9: kept_2026 | D9: 72.96
A10: ฝาก kept | B10: 46167 | C10: kept_2026 | D10: 5000
A11: คืนเงินเข้า kept | B11: 46141 | C11: kept_2026 | D11: 554
A12: ttb ss cashback | B12: 46141 | C12: kept_2026 | D12: 67.43
A13: ฝาก kept | B13: 46141 | C13: kept_2026 | D13: 375.06
A14: ดอกเบี้ย kept | B14: 46140 | C14: kept_2026 | F14: 261.53
A15: เอาไปจ่าย UOB เพราะจ่ายยอดผิดเดือน | B15: 46131 | C15: kept_2026 | E15: =2160+103.5 -> 2263.5
A16: เอาเงินกลับจาก crypto | B16: 46131 | C16: kept_2026 | D16: 20174.27
A17: ซื้อ crypto | B17: 46114 | C17: kept_2026 | E17: 15000
A18: เงินเหลืือจาก ttb sosmart | B18: 46111 | C18: kept_2026 | D18: 2242
A19: ดอกเบี้ย kept | B19: 46109 | C19: kept_2026 | F19: 279.63
A20: to kept | B20: 46111 | C20: kept_2026 | D20: 3583.57
A21: swap dime | B21: 46111 | C21: dime_2026 | E21: 3583.57
A22: เบียร์ @บางพระ | B22: 46109 | C22: dime_2026 | E22: 868.5
A23: รร hobb-in บางพระ | B23: 46109 | C23: dime_2026 | E23: 500
A24: ฝาก dime | B24: 46108 | C24: dime_2026 | D24: 2853
A25: ฝาก kept | B25: 46106 | C25: kept_2026 | D25: 11005.36
A26: ttb ss cashback | B26: 46104 | C26: kept_2026 | D26: 124.87
A27: ซื้อ crypto | B27: 46104 | C27: kept_2026 | E27: 15000
A28: ซองงานแต่งพี่อัด | B28: 46088 | C28: mbk_2026 | E28: 500
A29: TTB ss cashback | B29: 46083 | C29: kept_2026 | D29: 242.65
A30: ดอกเบี้ย kept | B30: 46081 | C30: kept_2026 | F30: 323.67
A31: ฝาก kept | B31: 46078 | C31: kept_2026 | D31: 700
A32: ฝาก dime | B32: 46078 | C32: dime_2026 | D32: 1088.36
A33: ดอกเบี้ย kept | B33: 46050 | C33: kept_2026 | F33: 315.89
A34: cashback so smart and เงินเหลือ | B34: 46047 | C34: kept_2026 | D34: 232.63
A35: ฝาก kept | B35: 46045 | C35: kept_2026 | D35: 3000
A36: ฝาก dime | B36: 46045 | C36: dime_2026 | D36: 1200
A37: ฝาก kept | B37: 46045 | C37: kept_2026 | D37: 700
A38: ฝาก dime | B38: 46045 | C38: dime_2026 | D38: 5600
A39: ฝาก mbk | B39: 46045 | C39: mbk_2026 | D39: 500
A40: ฝาก | B40: 46028 | C40: dime_2026 | D40: 269.02
A41: ย้ายออก | B41: 46024 | C41: blb_2026 | E41: 1000
A42: เอาเงิินไปเติม port | B42: 46017 | C42: dime_2025 | E42: 7059.63
A43: ดอกเบีีี้ย kept | B43: 46019 | C43: kept_2025 | F43: =177.87+0.09 -> 177.96
A44: ฝาก kept | B44: 46016 | C44: kept_2025 | D44: 25000
...

Sheet Memo
A1: Date | B1: Event Details
A3: 46106 | B3: ปรัับเงินขึ้น 6,332 บาท
A5: 45741 | B5: ปรับเงินเดือนขึ้น 2,657 บาท

Sheet Studentloan
A1: Date | B1: Amount | D1: Total Debt | E1: Total Pay | G1: Outstanding
A2: 45111 | B2: 1169.25 | D2: 177950 | E2: =SUM(B2:B1000) -> 71594.41 | G2: =D2-E2 -> 106355.59
A3: 45169 | B3: 517
A4: 45199 | B4: 517
A5: 45230 | B5: 517
A6: 45260 | B6: 517
A7: 45285 | B7: 4716.07
A8: 45291 | B8: 517
A9: 45349 | B9: 1100
A10: 45475 | B10: 2575
A11: 45480 | B11: 7072.66
A12: 45504 | B12: 588
A13: 45741 | B13: 1439
A14: 45772 | B14: 1643.86
... A30: 46167 | B30: 3000

Sheet Categories Wide
A1: Monthly Pay | B1: Food & Drink | C1: Transportation | D1: Service | E1: Health | F1: Items | G1: Investing | H1: Residence | I1: Travel | J1: Hobby | K1: Reimbursement | L1: Insurance | M1: Others | O1: Shop
A2: Salary | B2: อาหารหลัก (Main meals) | C2: Maintenance | D2: Subscription | E2: Activewear | F2: Household Items | G2: US Stock | H2: ค่าส่วนกลางหมู่บ้าน (Community Fees) | I2: Accommodation | J2: Tree | K2: Reimbursement | L2: Car Insurance | M2: Tax | O2: Thai Watsadu
A3: OT | B3: ของว่าง (Snacks) | C3: Toll Fee | D3: Haircut | E3: Exercise Equipment | F3: Personal Items | G3: TH Stock | H3: Home Renovation | I3: Food & Drink | J3: Camping | L3: Accident insurance | M3: Donation | O3: Auto 1
A4: Bonus | B4: เครื่องดื่ม (Drinks) | C4: Fuel | D4: Movie | E4: Sick | F4: Skincare | G4: TH Fund | H4: Electricity Bill-A | I4: Alcohol | J4: Computer | L4: Health Insurance | M4: Fine | O4: Major
A5: Freelance | B5: อาหารปรุงเอง (Groceries) | C5: ค่าที่จอดรถ, ค่าธรรมเนียมต่างๆ (Fee) | D5: Home Internet | E5: Accident | F5: Outfit | G5: Contigency | H5: Electricity Bill-B | I5: Fuel | J5: Education | M5: Lotto | O5: SF
A6: OT | B6: อาหารนอกบ้าน (Dine-out) | D6: Mobile Internet | F6: ของที่ใช้กับรถ (Vehicle) | H6: Water Bill | I6: ค่าที่จอดรถ (Fee) | J6: ของที่ใช้กับรถ (Vehicle) | M6: Dept | O6: Caltex
A7: Cashback | B7: อาหารเสริม (Supplement) | D7: Wash&Dry | I7: ค่่าบริการสถานที่ต่างๆ (Fee) | M7: Family | O7: Bangchak
A8: Dividend | B8: เครื่องดื่มแอลกอฮอล์ (Alcohol) | M8: Souvenirs | O8: PT Gas Station
A9: Interest | M9: Alcohol | O9: Watsons
M10: Fee | O10: Eve'nBoy
M11: Fuel | O11: 7-Eleven
M12: Vehicle | O12: Lotus
M13: Others | O13: Mc Donald
O14: Webtoon
O15: YT Premium
O16: Noodle
O17: Hainanese chicken rice
O18: Amazon
O19: KFC
O20: Subway
O21: Pad Kapow
O22: Pizza
O23: Bonchon
O24: Lucky Suki
O25: Ikea
... O34: Other

Sheet Payment Method
A1: Payment Method | B1: Reconciliation Day | C1: Credit Limit | D1: Benefits
A2: UOB One | B2: 7 | C2: 157000 | D2: Cashback: 10% -> MRT, Amazon 5% -> 7-11, Grab, Watson 1% -> other Get movie ticket 1 free 1 - ใช้ได้ 2ครั้ง/เดือน คุ้มครองอุบัติเหตุระหว่างการเดินทางสูงสุด 10,000,000 บาท ต่อบัตร เมื่อชำระค่าโดยสารผ่านบัตรเครดิต UOB One ค่าธรรมเนียม - ฟรีปีแรก - ปีถัดไป 2,000 บาท ยกเว้นใช้จ่ายไม่ต่ำกว่า 60,000 ภายใน 12 รอบบิล
A3: TTB So Smart | B3: 22 | C3: 56000 | D3: Cashback: 3% -> Bangchak (เติมแค่ 620), Caltex (เติมแค่ 720) 1% -> other (ร้านค้าในไทย) ผ่อน 0% นานสูงสุด 3 เดือน ยอด 1,000 ขึ้นไป ประกันอุบัติเหตุเมื่อชําระค่าโดยสารยานพาหนะสาธารณะผ่านบัตรเครดิต ฟรีค่าธรรมเนียมรายปี
A4: KTC Bangchak | B4: 5 | C4: 100000 | D4: Cashback: 1% -> Bangchak ไม่เกิน 3,000/เซลส์สลิป รับ 1 คะแนนทุก 25 บาท ผ่อน 0% นานสูงสุด 10 เดือน ประกันอุบัติเหตุการเดินทางทั้งในและต่างประเทศ และประกันกระเป๋าเดินทางสูญเสีย หรือเสียหายจากการเดินทาง ***เมื่อจ่ายค่าเดินทางด้วยบัตรนี้ ฟรีค่าธรรมเนียมรายปี
A5: Mobile Banking
A6: Cash

Sheet LongFormat
A1: Category | B1: Subcategory
A2: Monthly Pay | B2: Salary
A3: Monthly Pay | B3: Devidend
A4: Monthly Pay | B4: Interest
A5: Monthly Pay | B5: OT
A6: Monthly Pay | B6: Cashback
A7: Monthly Pay | B7: Bonus
A8: Monthly Pay | B8: Freelance
A9: Food & Drink | B9: Main meals
A10: Food & Drink | B10: Snacks
A11: Food & Drink | B11: Drinks
A12: Food & Drink | B12: Groceries
... A60: Items | B60: Vehicle
A61: Hobby
A62: Reimbursement | B62: Reimbursement

Sheet Background-Data
A1: Year | B1: Month | C1: Filter Category | E1: =IFERROR(__xludf.DUMMYFUNCTION("QUERY(Transaction!A1:J200, ""SELECT A, B, C, D, E, F, G, H WHERE B != 'Monthly Pay' AND B != 'Investment' AND B != 'Reimbursement' ""&IF('Monthly Dashboard'!C2<>""All"", ""AND B = '"" &'Monthly Dashboard'!C2& ""'"", """")&"" AND I = '""&'Monthly Dashboard"&"'!A2&""' AND J = '""&'Monthly Dashboard'!B2&""' ORDER BY A DESC"", 1)"),"Date") -> Date | F1: =IFERROR(__xludf.DUMMYFUNCTION("""COMPUTED_VALUE"""),"Category") -> Category | G1: =IFERROR(__xludf.DUMMYFUNCTION("""COMPUTED_VALUE"""),"Sub-Category") -> Sub-Category | H1: =IFERROR(__xludf.DUMMYFUNCTION("""COMPUTED_VALUE"""),"Amount") -> Amount | I1: =IFERROR(__xludf.DUMMYFUNCTION("""COMPUTED_VALUE"""),"Pay Medthod") -> Pay Medthod | J1: =IFERROR(__xludf.DUMMYFUNCTION("""COMPUTED_VALUE"""),"Status") -> Status | K1: =IFERROR(__xludf.DUMMYFUNCTION("""COMPUTED_VALUE"""),"Shop") -> Shop | L1: =IFERROR(__xludf.DUMMYFUNCTION("""COMPUTED_VALUE"""),"Note") -> Note
A2: {=SORT(UNIQUE(Transaction!I2:I200), 1, false)} -> _2025_ | B2: {=SORT(UNIQUE(Transaction!J2:J200), 1, false)} -> _9_ | C2: All | E2: =IFERROR(__xludf.DUMMYFUNCTION("""COMPUTED_VALUE"""),45960.0) -> 45960 | F2: =IFERROR(__xludf.DUMMYFUNCTION("""COMPUTED_VALUE"""),"Food & Drink") -> Food & Drink | G2: =IFERROR(__xludf.DUMMYFUNCTION("""COMPUTED_VALUE"""),"Main meals") -> Main meals | H2: =IFERROR(__xludf.DUMMYFUNCTION("""COMPUTED_VALUE"""),372.0) -> 372 | I2: =IFERROR(__xludf.DUMMYFUNCTION("""COMPUTED_VALUE"""),"UOB One") -> UOB One | J2: =IFERROR(__xludf.DUMMYFUNCTION("""COMPUTED_VALUE"""),"Credit Spending") -> Credit Spending | K2: =IFERROR(__xludf.DUMMYFUNCTION("""COMPUTED_VALUE"""),"Pizza") -> Pizza
B3: _8_ | C3: =IFERROR(__xludf.DUMMYFUNCTION("UNIQUE(QUERY(Transaction!A1:J200, ""SELECT B WHERE B != 'Monthly Pay' AND B != 'Reimbursement' AND B != 'Investment' AND I = '""&'Monthly Dashboard'!A2&""' AND J = '""&'Monthly Dashboard'!B2&""' ORDER BY A DESC"", 0))"),"Food & Drink") -> Food & Drink | E3: =IFERROR(__xludf.DUMMYFUNCTION("""COMPUTED_VALUE"""),45959.0) -> 45959 | F3: =IFERROR(__xludf.DUMMYFUNCTION("""COMPUTED_VALUE"""),"Hobby") -> Hobby | G3: =IFERROR(__xludf.DUMMYFUNCTION("""COMPUTED_VALUE"""),"Education") -> Education | H3: =IFERROR(__xludf.DUMMYFUNCTION("""COMPUTED_VALUE"""),719.0) -> 719 | I3: =IFERROR(__xludf.DUMMYFUNCTION("""COMPUTED_VALUE"""),"UOB One") -> UOB One | J3: =IFERROR(__xludf.DUMMYFUNCTION("""COMPUTED_VALUE"""),"Credit Spending") -> Credit Spending
B4: _7_ | C4: =IFERROR(__xludf.DUMMYFUNCTION("""COMPUTED_VALUE"""),"Hobby") -> Hobby | E4: =IFERROR(__xludf.DUMMYFUNCTION("""COMPUTED_VALUE"""),45959.0) -> 45959 | F4: =IFERROR(__xludf.DUMMYFUNCTION("""COMPUTED_VALUE"""),"Food & Drink") -> Food & Drink | G4: =IFERROR(__xludf.DUMMYFUNCTION("""COMPUTED_VALUE"""),"Main meals") -> Main meals | H4: =IFERROR(__xludf.DUMMYFUNCTION("""COMPUTED_VALUE"""),50.0) -> 50 | I4: =IFERROR(__xludf.DUMMYFUNCTION("""COMPUTED_VALUE"""),"Mobile Banking") -> Mobile Banking | K4: =IFERROR(__xludf.DUMMYFUNCTION("""COMPUTED_VALUE"""),"Hainanese chicken rice") -> Hainanese chicken rice
B5: _6_ | C5: =IFERROR(__xludf.DUMMYFUNCTION("""COMPUTED_VALUE"""),"Transportation") -> Transportation | E5: =IFERROR(__xludf.DUMMYFUNCTION("""COMPUTED_VALUE"""),45959.0) -> 45959 | F5: =IFERROR(__xludf.DUMMYFUNCTION("""COMPUTED_VALUE"""),"Food & Drink") -> Food & Drink | G5: =IFERROR(__xludf.DUMMYFUNCTION("""COMPUTED_VALUE"""),"Snacks") -> Snacks | H5: =IFERROR(__xludf.DUMMYFUNCTION("""COMPUTED_VALUE"""),36.0) -> 36 | I5: =IFERROR(__xludf.DUMMYFUNCTION("""COMPUTED_VALUE"""),"Mobile Banking") -> Mobile Banking | K5: =IFERROR(__xludf.DUMMYFUNCTION("""COMPUTED_VALUE"""),"CJ") -> CJ
B6: _5_ | C6: =IFERROR(__xludf.DUMMYFUNCTION("""COMPUTED_VALUE"""),"Others") -> Others | E6: =IFERROR(__xludf.DUMMYFUNCTION("""COMPUTED_VALUE"""),45957.0) -> 45957 | F6: =IFERROR(__xludf.DUMMYFUNCTION("""COMPUTED_VALUE"""),"Transportation") -> Transportation | G6: =IFERROR(__xludf.DUMMYFUNCTION("""COMPUTED_VALUE"""),"Maintenance") -> Maintenance | H6: =IFERROR(__xludf.DUMMYFUNCTION("""COMPUTED_VALUE"""),1883.2) -> 1883.2 | I6: =IFERROR(__xludf.DUMMYFUNCTION("""COMPUTED_VALUE"""),"Mobile Banking") -> Mobile Banking | J6: =IFERROR(__xludf.DUMMYFUNCTION("""COMPUTED_VALUE"""),"Credit Spending") -> Credit Spending | L6: =IFERROR(__xludf.DUMMYFUNCTION("""COMPUTED_VALUE"""),"เข้าเช็คระยะ 63,000 km") -> เข้าเช็คระยะ 63,000 km
B7: _4_ | C7: =IFERROR(__xludf.DUMMYFUNCTION("""COMPUTED_VALUE"""),"Items") -> Items | E7: =IFERROR(__xludf.DUMMYFUNCTION("""COMPUTED_VALUE"""),45957.0) -> 45957 | F7: =IFERROR(__xludf.DUMMYFUNCTION("""COMPUTED_VALUE"""),"Transportation") -> Transportation | G7: =IFERROR(__xludf.DUMMYFUNCTION("""COMPUTED_VALUE"""),"Fee") -> Fee | H7: =IFERROR(__xludf.DUMMYFUNCTION("""COMPUTED_VALUE"""),50.0) -> 50 | I7: =IFERROR(__xludf.DUMMYFUNCTION("""COMPUTED_VALUE"""),"Mobile Banking") -> Mobile Banking | L7: =IFERROR(__xludf.DUMMYFUNCTION("""COMPUTED_VALUE"""),"ค่าจอดรถสนามบินส่งมิ้น") -> ค่าจอดรถสนามบินส่งมิ้น
B8: _3_ | C8: =IFERROR(__xludf.DUMMYFUNCTION("""COMPUTED_VALUE"""),"Service") -> Service | E8: =IFERROR(__xludf.DUMMYFUNCTION("""COMPUTED_VALUE"""),45957.0) -> 45957 | F8: =IFERROR(__xludf.DUMMYFUNCTION("""COMPUTED_VALUE"""),"Food & Drink") -> Food & Drink | G8: =IFERROR(__xludf.DUMMYFUNCTION("""COMPUTED_VALUE"""),"Snacks") -> Snacks | H8: =IFERROR(__xludf.DUMMYFUNCTION("""COMPUTED_VALUE"""),204.0) -> 204 | I8: =IFERROR(__xludf.DUMMYFUNCTION("""COMPUTED_VALUE"""),"Mobile Banking") -> Mobile Banking | K8: =IFERROR(__xludf.DUMMYFUNCTION("""COMPUTED_VALUE"""),"7-Eleven") -> 7-Eleven | L8: =IFERROR(__xludf.DUMMYFUNCTION("""COMPUTED_VALUE"""),"ตั้งแต่วันที่ 27-29") -> ตั้งแต่วันที่ 27-29
B9: _2_ | C9: =IFERROR(__xludf.DUMMYFUNCTION("""COMPUTED_VALUE"""),"Residence") -> Residence | E9: =IFERROR(__xludf.DUMMYFUNCTION("""COMPUTED_VALUE"""),45956.0) -> 45956 | F9: =IFERROR(__xludf.DUMMYFUNCTION("""COMPUTED_VALUE"""),"Others") -> Others | G9: =IFERROR(__xludf.DUMMYFUNCTION("""COMPUTED_VALUE"""),"Others") -> Others | H9: =IFERROR(__xludf.DUMMYFUNCTION("""COMPUTED_VALUE"""),27.0) -> 27 | I9: =IFERROR(__xludf.DUMMYFUNCTION("""COMPUTED_VALUE"""),"Mobile Banking") -> Mobile Banking | L9: =IFERROR(__xludf.DUMMYFUNCTION("""COMPUTED_VALUE"""),"ค่าส่งหูฟัง soundcore") -> ค่าส่งหูฟัง soundcore
B10: _10_ | C10: =IFERROR(__xludf.DUMMYFUNCTION("""COMPUTED_VALUE"""),"Health") -> Health | E10: =IFERROR(__xludf.DUMMYFUNCTION("""COMPUTED_VALUE"""),45956.0) -> 45956 | F10: =IFERROR(__xludf.DUMMYFUNCTION("""COMPUTED_VALUE"""),"Food & Drink") -> Food & Drink | G10: =IFERROR(__xludf.DUMMYFUNCTION("""COMPUTED_VALUE"""),"Main meals") -> Main meals | H10: =IFERROR(__xludf.DUMMYFUNCTION("""COMPUTED_VALUE"""),85.0) -> 85 | I10: =IFERROR(__xludf.DUMMYFUNCTION("""COMPUTED_VALUE"""),"Mobile Banking") -> Mobile Banking | K10: =IFERROR(__xludf.DUMMYFUNCTION("""COMPUTED_VALUE"""),"Noodle") -> Noodle
B11: _1_ | E11: =IFERROR(__xludf.DUMMYFUNCTION("""COMPUTED_VALUE"""),45956.0) -> 45956 | F11: =IFERROR(__xludf.DUMMYFUNCTION("""COMPUTED_VALUE"""),"Food & Drink") -> Food & Drink | G11: =IFERROR(__xludf.DUMMYFUNCTION("""COMPUTED_VALUE"""),"Drinks") -> Drinks | H11: =IFERROR(__xludf.DUMMYFUNCTION("""COMPUTED_VALUE"""),40.0) -> 40 | I11: =IFERROR(__xludf.DUMMYFUNCTION("""COMPUTED_VALUE"""),"Mobile Banking") -> Mobile Banking | K11: =IFERROR(__xludf.DUMMYFUNCTION("""COMPUTED_VALUE"""),"CJ") -> CJ | L11: =IFERROR(__xludf.DUMMYFUNCTION("""COMPUTED_VALUE"""),"ชาไทย") -> ชาไทย
E12: =IFERROR(__xludf.DUMMYFUNCTION("""COMPUTED_VALUE"""),45956.0) -> 45956 | F12: =IFERROR(__xludf.DUMMYFUNCTION("""COMPUTED_VALUE"""),"Food & Drink") -> Food & Drink | G12: =IFERROR(__xludf.DUMMYFUNCTION("""COMPUTED_VALUE"""),"Groceries") -> Groceries | H12: =IFERROR(__xludf.DUMMYFUNCTION("""COMPUTED_VALUE"""),120.0) -> 120 | I12: =IFERROR(__xludf.DUMMYFUNCTION("""COMPUTED_VALUE"""),"Mobile Banking") -> Mobile Banking | L12: =IFERROR(__xludf.DUMMYFUNCTION("""COMPUTED_VALUE"""),"ผัก") -> ผัก
E13: =IFERROR(__xludf.DUMMYFUNCTION("""COMPUTED_VALUE"""),45956.0) -> 45956 | F13: =IFERROR(__xludf.DUMMYFUNCTION("""COMPUTED_VALUE"""),"Transportation") -> Transportation | G13: =IFERROR(__xludf.DUMMYFUNCTION("""COMPUTED_VALUE"""),"Maintenance") -> Maintenance | H13: =IFERROR(__xludf.DUMMYFUNCTION("""COMPUTED_VALUE"""),1000.0) -> 1000 | I13: =IFERROR(__xludf.DUMMYFUNCTION("""COMPUTED_VALUE"""),"Mobile Banking") -> Mobile Banking | J13: =IFERROR(__xludf.DUMMYFUNCTION("""COMPUTED_VALUE"""),"Credit Spending") -> Credit Spending | L13: =IFERROR(__xludf.DUMMYFUNCTION("""COMPUTED_VALUE"""),"เปลี่ยนคิ้วรถ") -> เปลี่ยนคิ้วรถ
E14: =IFERROR(__xludf.DUMMYFUNCTION("""COMPUTED_VALUE"""),45955.0) -> 45955 | F14: =IFERROR(__xludf.DUMMYFUNCTION("""COMPUTED_VALUE"""),"Food & Drink") -> Food & Drink | G14: =IFERROR(__xludf.DUMMYFUNCTION("""COMPUTED_VALUE"""),"Main meals") -> Main meals | H14: =IFERROR(__xludf.DUMMYFUNCTION("""COMPUTED_VALUE"""),80.0) -> 80 | I14: =IFERROR(__xludf.DUMMYFUNCTION("""COMPUTED_VALUE"""),"Mobile Banking") -> Mobile Banking | L14: =IFERROR(__xludf.DUMMYFUNCTION("""COMPUTED_VALUE"""),"กะเพรา") -> กะเพรา
E15: =IFERROR(__xludf.DUMMYFUNCTION("""COMPUTED_VALUE"""),45955.0) -> 45955 | F15: =IFERROR(__xludf.DUMMYFUNCTION("""COMPUTED_VALUE"""),"Food & Drink") -> Food & Drink | G15: =IFERROR(__xludf.DUMMYFUNCTION("""COMPUTED_VALUE"""),"Groceries") -> Groceries | H15: =IFERROR(__xludf.DUMMYFUNCTION("""COMPUTED_VALUE"""),162.0) -> 162 | I15: =IFERROR(__xludf.DUMMYFUNCTION("""COMPUTED_VALUE"""),"Mobile Banking") -> Mobile Banking | L15: =IFERROR(__xludf.DUMMYFUNCTION("""COMPUTED_VALUE"""),"ผัก") -> ผัก
E16: =IFERROR(__xludf.DUMMYFUNCTION("""COMPUTED_VALUE"""),45955.0) -> 45955 | F16: =IFERROR(__xludf.DUMMYFUNCTION("""COMPUTED_VALUE"""),"Food & Drink") -> Food & Drink | G16: =IFERROR(__xludf.DUMMYFUNCTION("""COMPUTED_VALUE"""),"Drinks") -> Drinks | H16: =IFERROR(__xludf.DUMMYFUNCTION("""COMPUTED_VALUE"""),40.0) -> 40 | I16: =IFERROR(__xludf.DUMMYFUNCTION("""COMPUTED_VALUE"""),"Mobile Banking") -> Mobile Banking | K16: =IFERROR(__xludf.DUMMYFUNCTION("""COMPUTED_VALUE"""),"CJ") -> CJ | L16: =IFERROR(__xludf.DUMMYFUNCTION("""COMPUTED_VALUE"""),"ชาไทย") -> ชาไทย
E17: =IFERROR(__xludf.DUMMYFUNCTION("""COMPUTED_VALUE"""),45955.0) -> 45955 | F17: =IFERROR(__xludf.DUMMYFUNCTION("""COMPUTED_VALUE"""),"Items") -> Items | G17: =IFERROR(__xludf.DUMMYFUNCTION("""COMPUTED_VALUE"""),"Household Items") -> Household Items | H17: =IFERROR(__xludf.DUMMYFUNCTION("""COMPUTED_VALUE"""),142.0) -> 142 | I17: =IFERROR(__xludf.DUMMYFUNCTION("""COMPUTED_VALUE"""),"TTB So Smart") -> TTB So Smart | J17: =IFERROR(__xludf.DUMMYFUNCTION("""COMPUTED_VALUE"""),"Credit Spending") -> Credit Spending | K17: =IFERROR(__xludf.DUMMYFUNCTION("""COMPUTED_VALUE"""),"Lotus") -> Lotus | L17: =IFERROR(__xludf.DUMMYFUNCTION("""COMPUTED_VALUE"""),"สำลี ครีมอาบน้ำไ") -> สำลี ครีมอาบน้ำไ
E18: =IFERROR(__xludf.DUMMYFUNCTION("""COMPUTED_VALUE"""),45955.0) -> 45955 | F18: =IFERROR(__xludf.DUMMYFUNCTION("""COMPUTED_VALUE"""),"Food & Drink") -> Food & Drink | G18: =IFERROR(__xludf.DUMMYFUNCTION("""COMPUTED_VALUE"""),"Groceries") -> Groceries | H18: =IFERROR(__xludf.DUMMYFUNCTION("""COMPUTED_VALUE"""),381.25) -> 381.25 | I18: =IFERROR(__xludf.DUMMYFUNCTION("""COMPUTED_VALUE"""),"TTB So Smart") -> TTB So Smart | J18: =IFERROR(__xludf.DUMMYFUNCTION("""COMPUTED_VALUE"""),"Credit Spending") -> Credit Spending | K18: =IFERROR(__xludf.DUMMYFUNCTION("""COMPUTED_VALUE"""),"Lotus") -> Lotus
E19: =IFERROR(__xludf.DUMMYFUNCTION("""COMPUTED_VALUE"""),45954.0) -> 45954 | F19: =IFERROR(__xludf.DUMMYFUNCTION("""COMPUTED_VALUE"""),"Others") -> Others | G19: =IFERROR(__xludf.DUMMYFUNCTION("""COMPUTED_VALUE"""),"Debt") -> Debt | H19: =IFERROR(__xludf.DUMMYFUNCTION("""COMPUTED_VALUE"""),8521.0) -> 8521 | I19: =IFERROR(__xludf.DUMMYFUNCTION("""COMPUTED_VALUE"""),"Mobile Banking") -> Mobile Banking | L19: =IFERROR(__xludf.DUMMYFUNCTION("""COMPUTED_VALUE"""),"ค่ารถงวด 39") -> ค่ารถงวด 39
E20: =IFERROR(__xludf.DUMMYFUNCTION("""COMPUTED_VALUE"""),45954.0) -> 45954 | F20: =IFERROR(__xludf.DUMMYFUNCTION("""COMPUTED_VALUE"""),"Others") -> Others | G20: =IFERROR(__xludf.DUMMYFUNCTION("""COMPUTED_VALUE"""),"Devidend") -> Devidend | H20: =IFERROR(__xludf.DUMMYFUNCTION("""COMPUTED_VALUE"""),2000.0) -> 2000 | I20: =IFERROR(__xludf.DUMMYFUNCTION("""COMPUTED_VALUE"""),"Mobile Banking") -> Mobile Banking | K20: =IFERROR(__xludf.DUMMYFUNCTION("""COMPUTED_VALUE"""),"Studentloan Debt") -> Studentloan Debt | L20: =IFERROR(__xludf.DUMMYFUNCTION("""COMPUTED_VALUE"""),"กยศ") -> กยศ
E21: =IFERROR(__xludf.DUMMYFUNCTION("""COMPUTED_VALUE"""),45954.0) -> 45954 | F21: =IFERROR(__xludf.DUMMYFUNCTION("""COMPUTED_VALUE"""),"Service") -> Service | G21: =IFERROR(__xludf.DUMMYFUNCTION("""COMPUTED_VALUE"""),"Home Internet") -> Home Internet | H21: =IFERROR(__xludf.DUMMYFUNCTION("""COMPUTED_VALUE"""),650.0) -> 650 | I21: =IFERROR(__xludf.DUMMYFUNCTION("""COMPUTED_VALUE"""),"Mobile Banking") -> Mobile Banking | L21: =IFERROR(__xludf.DUMMYFUNCTION("""COMPUTED_VALUE"""),"เน็ตบ้าน") -> เน็ตบ้าน
E22: =IFERROR(__xludf.DUMMYFUNCTION("""COMPUTED_VALUE"""),45954.0) -> 45954 | F22: =IFERROR(__xludf.DUMMYFUNCTION("""COMPUTED_VALUE"""),"Service") -> Service | G22: =IFERROR(__xludf.DUMMYFUNCTION("""COMPUTED_VALUE"""),"Mobile Internet") -> Mobile Internet | H22: =IFERROR(__xludf.DUMMYFUNCTION("""COMPUTED_VALUE"""),450.0) -> 450 | I22: =IFERROR(__xludf.DUMMYFUNCTION("""COMPUTED_VALUE"""),"Mobile Banking") -> Mobile Banking | L22: =IFERROR(__xludf.DUMMYFUNCTION("""COMPUTED_VALUE"""),"เน็็ตมือถือ") -> เน็็ตมือถือ
E23: =IFERROR(__xludf.DUMMYFUNCTION("""COMPUTED_VALUE"""),45954.0) -> 45954 | F23: =IFERROR(__xludf.DUMMYFUNCTION("""COMPUTED_VALUE"""),"Food & Drink") -> Food & Drink | G23: =IFERROR(__xludf.DUMMYFUNCTION("""COMPUTED_VALUE"""),"Main meals") -> Main meals | H23: =IFERROR(__xludf.DUMMYFUNCTION("""COMPUTED_VALUE"""),80.0) -> 80 | I23: =IFERROR(__xludf.DUMMYFUNCTION("""COMPUTED_VALUE"""),"Mobile Banking") -> Mobile Banking | L23: =IFERROR(__xludf.DUMMYFUNCTION("""COMPUTED_VALUE"""),"ข้าวมันไก่, ลูกชิ้น") -> ข้าวมันไก่, ลูกชิ้น
E24: =IFERROR(__xludf.DUMMYFUNCTION("""COMPUTED_VALUE"""),45954.0) -> 45954 | F24: =IFERROR(__xludf.DUMMYFUNCTION("""COMPUTED_VALUE"""),"Food & Drink") -> Food & Drink | G24: =IFERROR(__xludf.DUMMYFUNCTION("""COMPUTED_VALUE"""),"Main meals") -> Main meals | H24: =IFERROR(__xludf.DUMMYFUNCTION("""COMPUTED_VALUE"""),190.0) -> 190 | I24: =IFERROR(__xludf.DUMMYFUNCTION("""COMPUTED_VALUE"""),"UOB One") -> UOB One | J24: =IFERROR(__xludf.DUMMYFUNCTION("""COMPUTED_VALUE"""),"Credit Spending") -> Credit Spending | K24: =IFERROR(__xludf.DUMMYFUNCTION("""COMPUTED_VALUE"""),"Bonchon") -> Bonchon
E25: =IFERROR(__xludf.DUMMYFUNCTION("""COMPUTED_VALUE"""),45953.0) -> 45953 | F25: =IFERROR(__xludf.DUMMYFUNCTION("""COMPUTED_VALUE"""),"Food & Drink") -> Food & Drink | G25: =IFERROR(__xludf.DUMMYFUNCTION("""COMPUTED_VALUE"""),"Snacks") -> Snacks | H25: =IFERROR(__xludf.DUMMYFUNCTION("""COMPUTED_VALUE"""),37.0) -> 37 | I25: =IFERROR(__xludf.DUMMYFUNCTION("""COMPUTED_VALUE"""),"Mobile Banking") -> Mobile Banking | L25: =IFERROR(__xludf.DUMMYFUNCTION("""COMPUTED_VALUE"""),"โตเกียว") -> โตเกียว
E26: =IFERROR(__xludf.DUMMYFUNCTION("""COMPUTED_VALUE"""),45952.0) -> 45952 | F26: =IFERROR(__xludf.DUMMYFUNCTION("""COMPUTED_VALUE"""),"Food & Drink") -> Food & Drink | G26: =IFERROR(__xludf.DUMMYFUNCTION("""COMPUTED_VALUE"""),"Main meals") -> Main meals | H26: =IFERROR(__xludf.DUMMYFUNCTION("""COMPUTED_VALUE"""),153.0) -> 153 | I26: =IFERROR(__xludf.DUMMYFUNCTION("""COMPUTED_VALUE"""),"UOB One") -> UOB One | J26: =IFERROR(__xludf.DUMMYFUNCTION("""COMPUTED_VALUE"""),"Credit Spending") -> Credit Spending | K26: =IFERROR(__xludf.DUMMYFUNCTION("""COMPUTED_VALUE"""),"KFC") -> KFC
E27: =IFERROR(__xludf.DUMMYFUNCTION("""COMPUTED_VALUE"""),45952.0) -> 45952 | F27: =IFERROR(__xludf.DUMMYFUNCTION("""COMPUTED_VALUE"""),"Others") -> Others | G27: =IFERROR(__xludf.DUMMYFUNCTION("""COMPUTED_VALUE"""),"Others") -> Others | H27: =IFERROR(__xludf.DUMMYFUNCTION("""COMPUTED_VALUE"""),100.0) -> 100 | I27: =IFERROR(__xludf.DUMMYFUNCTION("""COMPUTED_VALUE"""),"Mobile Banking") -> Mobile Banking | L27: =IFERROR(__xludf.DUMMYFUNCTION("""COMPUTED_VALUE"""),"ให้พาย") -> ให้พาย
E28: =IFERROR(__xludf.DUMMYFUNCTION("""COMPUTED_VALUE"""),45951.0) -> 45951 | F28: =IFERROR(__xludf.DUMMYFUNCTION("""COMPUTED_VALUE"""),"Food & Drink") -> Food & Drink | G28: =IFERROR(__xludf.DUMMYFUNCTION("""COMPUTED_VALUE"""),"Main meals") -> Main meals | H28: =IFERROR(__xludf.DUMMYFUNCTION("""COMPUTED_VALUE"""),139.0) -> 139 | I28: =IFERROR(__xludf.DUMMYFUNCTION("""COMPUTED_VALUE"""),"TTB So Smart") -> TTB So Smart | J28: =IFERROR(__xludf.DUMMYFUNCTION("""COMPUTED_VALUE"""),"Credit Payment") -> Credit Payment | K28: =IFERROR(__xludf.DUMMYFUNCTION("""COMPUTED_VALUE"""),"Noodle") -> Noodle | L28: =IFERROR(__xludf.DUMMYFUNCTION("""COMPUTED_VALUE"""),"เตี๋ยวไก่") -> เตี๋ยวไก่
